{
 "cells": [
  {
   "cell_type": "code",
   "execution_count": 1,
   "metadata": {},
   "outputs": [
    {
     "name": "stderr",
     "output_type": "stream",
     "text": [
      "/home/conslag/anaconda3/lib/python3.7/importlib/_bootstrap.py:219: RuntimeWarning: numpy.ufunc size changed, may indicate binary incompatibility. Expected 192 from C header, got 216 from PyObject\n",
      "  return f(*args, **kwds)\n"
     ]
    }
   ],
   "source": [
    "import pymongo\n",
    "import numpy as np\n",
    "import pandas as pd\n",
    "import matplotlib.pyplot as plt\n",
    "plt.style.use('ggplot')\n",
    "plt.rcParams.update({'font.size': 18})\n",
    "\n",
    "# Make sure mongo docker running\n",
    "# init mongo connection\n",
    "conn = pymongo.MongoClient('localhost', 27017)\n",
    "db = conn['listings']"
   ]
  },
  {
   "cell_type": "code",
   "execution_count": 6,
   "metadata": {},
   "outputs": [
    {
     "data": {
      "text/plain": [
       "['search_metadata', 'listing_metadata']"
      ]
     },
     "execution_count": 6,
     "metadata": {},
     "output_type": "execute_result"
    }
   ],
   "source": [
    "# show collections\n",
    "db.list_collection_names()"
   ]
  },
  {
   "cell_type": "code",
   "execution_count": 8,
   "metadata": {},
   "outputs": [
    {
     "ename": "TypeError",
     "evalue": "'Collection' object is not callable. If you meant to call the 'findOne' method on a 'Collection' object it is failing because no such method exists.",
     "output_type": "error",
     "traceback": [
      "\u001b[0;31m---------------------------------------------------------------------------\u001b[0m",
      "\u001b[0;31mTypeError\u001b[0m                                 Traceback (most recent call last)",
      "\u001b[0;32m<ipython-input-8-cb838ab86e38>\u001b[0m in \u001b[0;36m<module>\u001b[0;34m\u001b[0m\n\u001b[1;32m      1\u001b[0m \u001b[0mcur\u001b[0m \u001b[0;34m=\u001b[0m \u001b[0mdb\u001b[0m\u001b[0;34m.\u001b[0m\u001b[0mlisting_metadata\u001b[0m\u001b[0;34m\u001b[0m\u001b[0;34m\u001b[0m\u001b[0m\n\u001b[0;32m----> 2\u001b[0;31m \u001b[0mcur\u001b[0m\u001b[0;34m.\u001b[0m\u001b[0mfindOne\u001b[0m\u001b[0;34m(\u001b[0m\u001b[0;34m)\u001b[0m\u001b[0;34m\u001b[0m\u001b[0;34m\u001b[0m\u001b[0m\n\u001b[0m",
      "\u001b[0;32m~/anaconda3/lib/python3.7/site-packages/pymongo/collection.py\u001b[0m in \u001b[0;36m__call__\u001b[0;34m(self, *args, **kwargs)\u001b[0m\n\u001b[1;32m   3341\u001b[0m                         \u001b[0;34m\"call the '%s' method on a 'Collection' object it is \"\u001b[0m\u001b[0;34m\u001b[0m\u001b[0;34m\u001b[0m\u001b[0m\n\u001b[1;32m   3342\u001b[0m                         \u001b[0;34m\"failing because no such method exists.\"\u001b[0m \u001b[0;34m%\u001b[0m\u001b[0;34m\u001b[0m\u001b[0;34m\u001b[0m\u001b[0m\n\u001b[0;32m-> 3343\u001b[0;31m                         self.__name.split(\".\")[-1])\n\u001b[0m",
      "\u001b[0;31mTypeError\u001b[0m: 'Collection' object is not callable. If you meant to call the 'findOne' method on a 'Collection' object it is failing because no such method exists."
     ]
    }
   ],
   "source": [
    "cur = db.listing_metadata\n",
    "cur.findOne()"
   ]
  },
  {
   "cell_type": "code",
   "execution_count": null,
   "metadata": {},
   "outputs": [],
   "source": []
  }
 ],
 "metadata": {
  "kernelspec": {
   "display_name": "Python 3",
   "language": "python",
   "name": "python3"
  },
  "language_info": {
   "codemirror_mode": {
    "name": "ipython",
    "version": 3
   },
   "file_extension": ".py",
   "mimetype": "text/x-python",
   "name": "python",
   "nbconvert_exporter": "python",
   "pygments_lexer": "ipython3",
   "version": "3.7.7"
  }
 },
 "nbformat": 4,
 "nbformat_minor": 4
}
